Workbook

Sheet Employee_Master_Raw
A1: Employee ID | B1: Employee Name | C1: Gender | D1: Age | E1: Department | F1: Job Role | G1: Location | H1: Joining Date | I1: Education | J1: Years of Experience | K1: Manager
A2: EMP10333 | B2: Priya Menon | C2: Male | D2: 30 | E2: Marketing | F2: Specialist | G2: Pune | H2: 45792 | I2: MBA | J2: 2 | K2: Sneha Thomas
A3: EMP12572 | B3: Amit Das | C3: Female | D3: 27 | E3: Operations | F3: Developer | G3: Kochi | H3: 43046 | I3: Bachelor's | J3: 13 | K3: Priya Sharma
A4: EMP12700 | B4: Ananya Sharma | C4: Male | D4: 54 | E4: Operations | F4: Analyst | G4: Delhi | H4: 45396 | I4: Bachelor's | J4: 15 | K4: Anil Menon
A5: EMP10337 | B5: Amit Das | C5: Female | D5: 42 | E5: IT | F5: Developer | G5: Chennai | H5: 45680 | I5: Bachelor's | J5: 13 | K5: Unknown
A6: EMP11917 | B6: Priya Menon | C6: Male | D6: 47 | E6: Sales | F6: Analyst | G6: Hyderabad | H6: 42615 | I6: Bachelor's | J6: 17 | K6: Sneha Thomas
A7: EMP11903 | B7: Kiran Patel | C7: Female | D7: 34 | E7: Finance | F7: Specialist | G7: Mumbai | H7: 44478 | I7: MBA | J7: 8 | K7: Anil Menon
A8: EMP11719 | B8: Rahul Kumar | C8: Male | D8: 38 | E8: IT | F8: Executive | G8: Bangalore | H8: 42981 | I8: MCA | J8: 3 | K8: Priya Sharma
A9: EMP12186 | B9: Priya Menon | C9: Female | D9: 54 | E9: Marketing | F9: Developer | G9: Delhi | H9: 42917 | I9: MCA | J9: 10 | K9: Sneha Thomas
A10: EMP10266 | B10: Neha Thomas | C10: Female | D10: 24 | E10: IT | F10: Specialist | G10: Delhi | H10: 43903 | I10: MCA | J10: 6 | K10: Sneha Thomas
A11: EMP11309 | B11: Rahul Kumar | C11: Female | D11: 51 | E11: Finance | F11: Executive | G11: Kochi | H11: 42445 | I11: MCA | J11: 2 | K11: Sneha Thomas
A12: EMP10931 | B12: Neha Thomas | C12: Female | D12: 24 | E12: IT | F12: Manager | G12: Kochi | H12: 43102 | I12: MBA | J12: 13 | K12: Unknown
A13: EMP11482 | B13: Ananya Sharma | C13: Male | D13: 29 | E13: Finance | F13: Manager | G13: Bangalore | H13: 44234 | I13: MCA | J13: 18 | K13: Anil Menon
... A164: EMP10172 | B164: Ananya Sharma | C164: Female | D164: 33 | E164: Operations | F164: Developer | G164: Chennai | H164: 42710 | I164: MBA | J164: 16 | K164: Sneha Thomas
A165: EMP12013 | B165: Arjun Nair | C165: Female | D165: 23 | E165: Finance | F165: Developer | G165: Chennai | I165: Master's | J165: 10 | K165: Rahul Nair
A166: EMP11611 | B166: Sneha Iyer | C166: Male | D166: 23 | E166: IT | F166: Executive | G166: Pune | H166: 43087 | I166: Master's | J166: 1 | K166: Rahul Nair
A167: EMP11764 | B167: Neha Thomas | C167: Male | D167: 57 | E167: Marketing | F167: Specialist | G167: Hyderabad | H167: 42818 | I167: Bachelor's | J167: 14 | K167: Priya Sharma
A168: EMP12371 | B168: Ananya Sharma | C168: Female | D168: 59 | E168: Operations | F168: Analyst | G168: Pune | H168: 45096 | I168: Master's | J168: 0 | K168: Priya Sharma
A169: EMP11625 | B169: Neha Thomas | C169: Male | D169: 56 | E169: Customer Support | F169: Analyst | G169: Chennai | H169: 44836 | I169: MCA | J169: 9 | K169: Anil Menon
A170: EMP12278 | B170: Ananya Sharma | C170: Female | D170: 49 | E170: FINANCE | F170: Specialist | G170: Hyderabad | H170: 43693 | I170: MCA | J170: 6 | K170: Priya Sharma
A171: EMP11976 | B171: Ananya Sharma | C171: Female | D171: 39 | E171: HR | F171: Analyst | G171: Bangalore | H171: 45344 | I171: MCA | J171: 0 | K171: Sneha Thomas
A172: EMP12176 | B172: Sneha Iyer | C172: Male | D172: 45 | E172: IT | F172: Executive | G172: Hyderabad | H172: 45400 | I172: Bachelor's | J172: 2 | K172: Priya Sharma
A173: EMP12217 | B173: Rahul Kumar | C173: Female | D173: 44 | E173: Sales | F173: Analyst | G173: Mumbai | H173: 44153 | I173: MCA | J173: 7 | K173: Priya Sharma
A174: EMP10581 | B174: Ananya Sharma | C174: Female | D174: 39 | E174: Sales | F174: Manager | G174: Chennai | H174: 45790 | I174: Bachelor's | J174: 7 | K174: Sneha Thomas
A175: EMP12833 | B175: Priya Menon | C175: Female | D175: 59 | E175: Marketing | F175: Manager | G175: Mumbai | H175: 46006 | I175: MBA | J175: 2 | K175: Rahul Nair
A176: EMP10678 | B176: Ananya Sharma | C176: Female | D176: 32 | E176: Finance | F176: Analyst | G176: Pune | H176: 44483 | I176: Bachelor's | J176: 15 | K176: Rahul Nair
A177: EMP11158 | B177: Sneha Iyer | C177: Male | D177: 50 | E177: FINANCE | F177: Developer | G177: Delhi | H177: 42808 | I177: Bachelor's | J177: 5 | K177: Priya Sharma
... A189: EMP10153 | B189: Amit Das | C189: Male | D189: 47 | E189: IT | F189: Specialist | G189: Hyderabad | H189: 43649 | I189: Master's | J189: 12 | K189: Sneha Thomas
A190: EMP12293 | B190: Arjun Nair | C190: Male | D190: 23 | E190: Operations | F190: Analyst | G190: Mumbai | I190: Master's | J190: 9 | K190: Anil Menon
A191: EMP12764 | B191: Ananya Sharma | C191: Male | D191: 33 | E191: HR | F191: Executive | G191: Delhi | H191: 44614 | I191: MCA | J191: 9 | K191: Sneha Thomas
A192: EMP12782 | B192: Amit Das | C192: Male | D192: 29 | E192: Customer Support | F192: Executive | G192: Pune | H192: 44865 | I192: Master's | J192: 16 | K192: Sneha Thomas
A193: EMP11965 | B193: Sneha Iyer | C193: Female | D193: 23 | E193: IT | F193: Manager | G193: Mumbai | H193: 43673 | I193: Master's | J193: 5 | K193: Anil Menon
A194: EMP12075 | B194: Kiran Patel | C194: Male | D194: 53 | E194: HR | F194: Developer | G194: Kochi | H194: 45799 | I194: Master's | J194: 17 | K194: Rahul Nair
A195: EMP10335 | B195: Rahul Kumar | C195: Male | D195: 23 | E195: Customer Support | F195: Specialist | G195: Hyderabad | I195: MCA | J195: 17 | K195: Rahul Nair
A196: EMP11026 | B196: Ananya Sharma | C196: Male | D196: 60 | E196: HR | F196: Analyst | G196: Mumbai | H196: 43284 | I196: MBA | J196: 5 | K196: Sneha Thomas
A197: EMP11062 | B197: Kiran Patel | C197: Male | D197: 22 | E197: Finance | F197: Executive | G197: Mumbai | H197: 44348 | I197: Master's | J197: 3 | K197: Priya Sharma
A198: EMP10588 | B198: Ananya Sharma | C198: Female | D198: 40 | E198: Customer Support | F198: Developer | G198: Chennai | H198: 42671 | I198: MCA | J198: 13 | K198: Rahul Nair
A199: EMP10759 | B199: Arjun Nair | C199: Male | D199: 32 | E199: Customer Support | F199: Developer | G199: Hyderabad | H199: 42844 | I199: Bachelor's | J199: 11 | K199: Anil Menon
A200: EMP11799 | B200: Rahul Kumar | C200: Male | D200: 42 | E200: Finance | F200: Manager | G200: Delhi | H200: 43571 | I200: Master's | J200: 8 | K200: Priya Sharma
A201: EMP11486 | B201: Sneha Iyer | C201: Male | D201: 55 | E201: IT | F201: Analyst | G201: Delhi | H201: 44474 | I201: MBA | J201: 4 | K201: Sneha Thomas
...

Sheet HR_Metrics_Raw
A1: Employee ID | B1: Monthly Salary | C1: Performance Rating | D1: Job Satisfaction | E1: Attendance % | F1: Leave Days | G1: Leave Type | H1: Overtime | I1: Training Hours | J1: Promotion Status | K1: Attrition
A2: EMP11766 | B2: 69681 | C2: 5 | D2: 4 | E2: 0.884 | F2: 9 | G2: Casual | H2: No | I2: 43 | J2: No | K2: Yes
A3: EMP12494 | B3: 107903 | C3: 5 | D3: 1 | E3: 0.81 | F3: 4 | G3: Unpaid | H3: No | I3: 51 | J3: No | K3: No
A4: EMP11056 | B4: 148688 | C4: 2 | D4: 3 | E4: 0.901 | F4: 12 | G4: Casual | H4: No | I4: 11 | J4: No | K4: No
A5: EMP11933 | B5: 90364 | C5: 3 | D5: 10 | E5: 0.819 | F5: 8 | G5: Earned | H5: Yes | I5: 75 | J5: No | K5: No
A6: EMP11155 | B6: 58937 | C6: 5 | D6: 10 | E6: 0.836 | F6: 18 | G6: Sick | H6: No | I6: 62 | J6: No | K6: No
A7: EMP10332 | B7: 55294 | C7: 1 | D7: 1 | E7: 0.897 | F7: 23 | G7: Maternity/Paternity | H7: No | I7: 45 | J7: Yes | K7: No
A8: EMP12531 | B8: 179676 | C8: 3 | D8: 6 | E8: 1 | F8: 28 | G8: Casual | H8: No | I8: 60 | J8: No | K8: No
A9: EMP11621 | B9: 173440 | C9: 1 | D9: 5 | E9: 0.919 | F9: 1 | G9: Sick | H9: Yes | I9: 25 | J9: No | K9: No
A10: EMP12522 | B10: 37409 | C10: 4 | D10: 6 | E10: 0.976 | F10: 28 | G10: Unknown | H10: No | I10: 51 | J10: No | K10: No
A11: EMP11646 | B11: 105129 | C11: 5 | D11: 9 | E11: 0.917 | F11: 21 | G11: Maternity/Paternity | H11: No | I11: 35 | J11: No | K11: No
A12: EMP10183 | B12: 46078 | C12: 4 | D12: 3 | E12: 0.845 | F12: 23 | G12: Earned | H12: No | I12: 54 | J12: No | K12: No
A13: EMP11017 | B13: 53396 | C13: 1 | D13: 8 | E13: 1 | F13: 13 | G13: Maternity/Paternity | H13: No | I13: 17 | J13: No | K13: Yes
... A3001: EMP11147 | B3001: 126039 | C3001: 3 | D3001: 9 | E3001: 1 | F3001: 0 | G3001: Unpaid | H3001: Yes | I3001: 14 | J3001: No | K3001: No

Sheet Final_HR_Data
A1: Employee ID | B1: Emploee Name | C1: Gender | D1: Age | E1: Department | F1: Job Role | G1: Location | H1: Joining Date | I1: Education | J1: Years Of Experience | K1: Manager | L1: Monthly Salary | M1: Performance Rating | N1: Job Satisfaction | O1: Attendence % | P1: Leave Days | Q1: Leave Type | R1: Overtime | S1: Training Hours | T1: Promotion Status | U1: Attrition
A2: EMP11766 | B2: =VLOOKUP(Final_HR_Data!A2,Employee_Master_Raw!$1:$1048576,2,FALSE) -> Amit Das | C2: =VLOOKUP(A2,Employee_Master_Raw!$1:$1048576,3,FALSE) -> Male | D2: =VLOOKUP(A2,Employee_Master_Raw!$1:$1048576,4,FALSE) -> 49 | E2: =VLOOKUP(A2,Employee_Master_Raw!$1:$1048576,5,FALSE) -> Operations | F2: =VLOOKUP(A2,Employee_Master_Raw!$1:$1048576,6,FALSE) -> Executive | G2: =VLOOKUP(A2,Employee_Master_Raw!$1:$1048576,7,FALSE) -> Bangalore | H2: =IF(VLOOKUP(A2,Employee_Master_Raw!$1:$1048576,8,FALSE)=0,"",VLOOKUP(A2,Employee_Master_Raw!$1:$1048576,8,FALSE)) -> 44731 | I2: =VLOOKUP(A2,Employee_Master_Raw!$1:$1048576,9,FALSE) -> Master's | J2: =VLOOKUP(A2,Employee_Master_Raw!$1:$1048576,10,FALSE) -> 6 | K2: =VLOOKUP(A2,Employee_Master_Raw!$1:$1048576,11,FALSE) -> Rahul Nair | L2: =VLOOKUP(A2,HR_Metrics_Raw!$1:$1048576,2,FALSE) -> 69681 | M2: =VLOOKUP(A2,HR_Metrics_Raw!$1:$1048576,3,FALSE) -> 5 | N2: =VLOOKUP(A2,HR_Metrics_Raw!$1:$1048576,4,FALSE) -> 4 | O2: =VLOOKUP(A2,HR_Metrics_Raw!$1:$1048576,5,FALSE) -> 0.884 | P2: =VLOOKUP(A2,HR_Metrics_Raw!$1:$1048576,6,FALSE) -> 9 | Q2: =VLOOKUP(A2,HR_Metrics_Raw!$1:$1048576,7,FALSE) -> Casual | R2: =VLOOKUP(A2,HR_Metrics_Raw!$1:$1048576,8,FALSE) -> No | S2: =VLOOKUP(A2,HR_Metrics_Raw!$1:$1048576,9,FALSE) -> 43 | T2: =VLOOKUP(A2,HR_Metrics_Raw!$1:$1048576,10,FALSE) -> No | U2: =VLOOKUP(A2,HR_Metrics_Raw!$1:$1048576,11,FALSE) -> Yes
A3: EMP12494 | B3: =VLOOKUP(Final_HR_Data!A3,Employee_Master_Raw!$1:$1048576,2,FALSE) -> Neha Thomas | C3: =VLOOKUP(A3,Employee_Master_Raw!$1:$1048576,3,FALSE) -> Male | D3: =VLOOKUP(A3,Employee_Master_Raw!$1:$1048576,4,FALSE) -> 55 | E3: =VLOOKUP(A3,Employee_Master_Raw!$1:$1048576,5,FALSE) -> HR | F3: =VLOOKUP(A3,Employee_Master_Raw!$1:$1048576,6,FALSE) -> Developer | G3: =VLOOKUP(A3,Employee_Master_Raw!$1:$1048576,7,FALSE) -> Mumbai | H3: =IF(VLOOKUP(A3,Employee_Master_Raw!$1:$1048576,8,FALSE)=0,"",VLOOKUP(A3,Employee_Master_Raw!$1:$1048576,8,FALSE)) -> 42543 | I3: =VLOOKUP(A3,Employee_Master_Raw!$1:$1048576,9,FALSE) -> Master's | J3: =VLOOKUP(A3,Employee_Master_Raw!$1:$1048576,10,FALSE) -> 20 | K3: =VLOOKUP(A3,Employee_Master_Raw!$1:$1048576,11,FALSE) -> Priya Sharma | L3: =VLOOKUP(A3,HR_Metrics_Raw!$1:$1048576,2,FALSE) -> 107903 | M3: =VLOOKUP(A3,HR_Metrics_Raw!$1:$1048576,3,FALSE) -> 5 | N3: =VLOOKUP(A3,HR_Metrics_Raw!$1:$1048576,4,FALSE) -> 1 | O3: =VLOOKUP(A3,HR_Metrics_Raw!$1:$1048576,5,FALSE) -> 0.81 | P3: =VLOOKUP(A3,HR_Metrics_Raw!$1:$1048576,6,FALSE) -> 4 | Q3: =VLOOKUP(A3,HR_Metrics_Raw!$1:$1048576,7,FALSE) -> Unpaid | R3: =VLOOKUP(A3,HR_Metrics_Raw!$1:$1048576,8,FALSE) -> No | S3: =VLOOKUP(A3,HR_Metrics_Raw!$1:$1048576,9,FALSE) -> 51 | T3: =VLOOKUP(A3,HR_Metrics_Raw!$1:$1048576,10,FALSE) -> No | U3: =VLOOKUP(A3,HR_Metrics_Raw!$1:$1048576,11,FALSE) -> No
A4: EMP11056 | B4: =VLOOKUP(Final_HR_Data!A4,Employee_Master_Raw!$1:$1048576,2,FALSE) -> Amit Das | C4: =VLOOKUP(A4,Employee_Master_Raw!$1:$1048576,3,FALSE) -> Male | D4: =VLOOKUP(A4,Employee_Master_Raw!$1:$1048576,4,FALSE) -> 27 | E4: =VLOOKUP(A4,Employee_Master_Raw!$1:$1048576,5,FALSE) -> IT | F4: =VLOOKUP(A4,Employee_Master_Raw!$1:$1048576,6,FALSE) -> Analyst | G4: =VLOOKUP(A4,Employee_Master_Raw!$1:$1048576,7,FALSE) -> Pune | H4: =IF(VLOOKUP(A4,Employee_Master_Raw!$1:$1048576,8,FALSE)=0,"",VLOOKUP(A4,Employee_Master_Raw!$1:$1048576,8,FALSE)) -> 42672 | I4: =VLOOKUP(A4,Employee_Master_Raw!$1:$1048576,9,FALSE) -> MCA | J4: =VLOOKUP(A4,Employee_Master_Raw!$1:$1048576,10,FALSE) -> 0 | K4: =VLOOKUP(A4,Employee_Master_Raw!$1:$1048576,11,FALSE) -> Rahul Nair | L4: =VLOOKUP(A4,HR_Metrics_Raw!$1:$1048576,2,FALSE) -> 148688 | M4: =VLOOKUP(A4,HR_Metrics_Raw!$1:$1048576,3,FALSE) -> 2 | N4: =VLOOKUP(A4,HR_Metrics_Raw!$1:$1048576,4,FALSE) -> 3 | O4: =VLOOKUP(A4,HR_Metrics_Raw!$1:$1048576,5,FALSE) -> 0.901 | P4: =VLOOKUP(A4,HR_Metrics_Raw!$1:$1048576,6,FALSE) -> 12 | Q4: =VLOOKUP(A4,HR_Metrics_Raw!$1:$1048576,7,FALSE) -> Casual | R4: =VLOOKUP(A4,HR_Metrics_Raw!$1:$1048576,8,FALSE) -> No | S4: =VLOOKUP(A4,HR_Metrics_Raw!$1:$1048576,9,FALSE) -> 11 | T4: =VLOOKUP(A4,HR_Metrics_Raw!$1:$1048576,10,FALSE) -> No | U4: =VLOOKUP(A4,HR_Metrics_Raw!$1:$1048576,11,FALSE) -> No
A5: EMP11933 | B5: =VLOOKUP(Final_HR_Data!A5,Employee_Master_Raw!$1:$1048576,2,FALSE) -> Sneha Iyer | C5: =VLOOKUP(A5,Employee_Master_Raw!$1:$1048576,3,FALSE) -> Female | D5: =VLOOKUP(A5,Employee_Master_Raw!$1:$1048576,4,FALSE) -> 37 | E5: =VLOOKUP(A5,Employee_Master_Raw!$1:$1048576,5,FALSE) -> HR | F5: =VLOOKUP(A5,Employee_Master_Raw!$1:$1048576,6,FALSE) -> Executive | G5: =VLOOKUP(A5,Employee_Master_Raw!$1:$1048576,7,FALSE) -> Bangalore | H5: =IF(VLOOKUP(A5,Employee_Master_Raw!$1:$1048576,8,FALSE)=0,"",VLOOKUP(A5,Employee_Master_Raw!$1:$1048576,8,FALSE)) -> 42651 | I5: =VLOOKUP(A5,Employee_Master_Raw!$1:$1048576,9,FALSE) -> MCA | J5: =VLOOKUP(A5,Employee_Master_Raw!$1:$1048576,10,FALSE) -> 18 | K5: =VLOOKUP(A5,Employee_Master_Raw!$1:$1048576,11,FALSE) -> Priya Sharma | L5: =VLOOKUP(A5,HR_Metrics_Raw!$1:$1048576,2,FALSE) -> 90364 | M5: =VLOOKUP(A5,HR_Metrics_Raw!$1:$1048576,3,FALSE) -> 3 | N5: =VLOOKUP(A5,HR_Metrics_Raw!$1:$1048576,4,FALSE) -> 10 | O5: =VLOOKUP(A5,HR_Metrics_Raw!$1:$1048576,5,FALSE) -> 0.819 | P5: =VLOOKUP(A5,HR_Metrics_Raw!$1:$1048576,6,FALSE) -> 8 | Q5: =VLOOKUP(A5,HR_Metrics_Raw!$1:$1048576,7,FALSE) -> Earned | R5: =VLOOKUP(A5,HR_Metrics_Raw!$1:$1048576,8,FALSE) -> Yes | S5: =VLOOKUP(A5,HR_Metrics_Raw!$1:$1048576,9,FALSE) -> 75 | T5: =VLOOKUP(A5,HR_Metrics_Raw!$1:$1048576,10,FALSE) -> No | U5: =VLOOKUP(A5,HR_Metrics_Raw!$1:$1048576,11,FALSE) -> No
A6: EMP11155 | B6: =VLOOKUP(Final_HR_Data!A6,Employee_Master_Raw!$1:$1048576,2,FALSE) -> Priya Menon | C6: =VLOOKUP(A6,Employee_Master_Raw!$1:$1048576,3,FALSE) -> Male | D6: =VLOOKUP(A6,Employee_Master_Raw!$1:$1048576,4,FALSE) -> 37 | E6: =VLOOKUP(A6,Employee_Master_Raw!$1:$1048576,5,FALSE) -> Sales | F6: =VLOOKUP(A6,Employee_Master_Raw!$1:$1048576,6,FALSE) -> Developer | G6: =VLOOKUP(A6,Employee_Master_Raw!$1:$1048576,7,FALSE) -> Pune | H6: =IF(VLOOKUP(A6,Employee_Master_Raw!$1:$1048576,8,FALSE)=0,"",VLOOKUP(A6,Employee_Master_Raw!$1:$1048576,8,FALSE)) -> 42947 | I6: =VLOOKUP(A6,Employee_Master_Raw!$1:$1048576,9,FALSE) -> MCA | J6: =VLOOKUP(A6,Employee_Master_Raw!$1:$1048576,10,FALSE) -> 3 | K6: =VLOOKUP(A6,Employee_Master_Raw!$1:$1048576,11,FALSE) -> Rahul Nair | L6: =VLOOKUP(A6,HR_Metrics_Raw!$1:$1048576,2,FALSE) -> 58937 | M6: =VLOOKUP(A6,HR_Metrics_Raw!$1:$1048576,3,FALSE) -> 5 | N6: =VLOOKUP(A6,HR_Metrics_Raw!$1:$1048576,4,FALSE) -> 10 | O6: =VLOOKUP(A6,HR_Metrics_Raw!$1:$1048576,5,FALSE) -> 0.836 | P6: =VLOOKUP(A6,HR_Metrics_Raw!$1:$1048576,6,FALSE) -> 18 | Q6: =VLOOKUP(A6,HR_Metrics_Raw!$1:$1048576,7,FALSE) -> Sick | R6: =VLOOKUP(A6,HR_Metrics_Raw!$1:$1048576,8,FALSE) -> No | S6: =VLOOKUP(A6,HR_Metrics_Raw!$1:$1048576,9,FALSE) -> 62 | T6: =VLOOKUP(A6,HR_Metrics_Raw!$1:$1048576,10,FALSE) -> No | U6: =VLOOKUP(A6,HR_Metrics_Raw!$1:$1048576,11,FALSE) -> No
A7: EMP10332 | B7: =VLOOKUP(Final_HR_Data!A7,Employee_Master_Raw!$1:$1048576,2,FALSE) -> Priya Menon | C7: =VLOOKUP(A7,Employee_Master_Raw!$1:$1048576,3,FALSE) -> Female | D7: =VLOOKUP(A7,Employee_Master_Raw!$1:$1048576,4,FALSE) -> 48 | E7: =VLOOKUP(A7,Employee_Master_Raw!$1:$1048576,5,FALSE) -> IT | F7: =VLOOKUP(A7,Employee_Master_Raw!$1:$1048576,6,FALSE) -> Specialist | G7: =VLOOKUP(A7,Employee_Master_Raw!$1:$1048576,7,FALSE) -> Hyderabad | H7: =IF(VLOOKUP(A7,Employee_Master_Raw!$1:$1048576,8,FALSE)=0,"",VLOOKUP(A7,Employee_Master_Raw!$1:$1048576,8,FALSE)) -> 43821 | I7: =VLOOKUP(A7,Employee_Master_Raw!$1:$1048576,9,FALSE) -> MBA | J7: =VLOOKUP(A7,Employee_Master_Raw!$1:$1048576,10,FALSE) -> 1 | K7: =VLOOKUP(A7,Employee_Master_Raw!$1:$1048576,11,FALSE) -> Priya Sharma | L7: =VLOOKUP(A7,HR_Metrics_Raw!$1:$1048576,2,FALSE) -> 55294 | M7: =VLOOKUP(A7,HR_Metrics_Raw!$1:$1048576,3,FALSE) -> 1 | N7: =VLOOKUP(A7,HR_Metrics_Raw!$1:$1048576,4,FALSE) -> 1 | O7: =VLOOKUP(A7,HR_Metrics_Raw!$1:$1048576,5,FALSE) -> 0.897 | P7: =VLOOKUP(A7,HR_Metrics_Raw!$1:$1048576,6,FALSE) -> 23 | Q7: =VLOOKUP(A7,HR_Metrics_Raw!$1:$1048576,7,FALSE) -> Maternity/Paternity | R7: =VLOOKUP(A7,HR_Metrics_Raw!$1:$1048576,8,FALSE) -> No | S7: =VLOOKUP(A7,HR_Metrics_Raw!$1:$1048576,9,FALSE) -> 45 | T7: =VLOOKUP(A7,HR_Metrics_Raw!$1:$1048576,10,FALSE) -> Yes | U7: =VLOOKUP(A7,HR_Metrics_Raw!$1:$1048576,11,FALSE) -> No
A8: EMP12531 | B8: =VLOOKUP(Final_HR_Data!A8,Employee_Master_Raw!$1:$1048576,2,FALSE) -> Amit Das | C8: =VLOOKUP(A8,Employee_Master_Raw!$1:$1048576,3,FALSE) -> Female | D8: =VLOOKUP(A8,Employee_Master_Raw!$1:$1048576,4,FALSE) -> 49 | E8: =VLOOKUP(A8,Employee_Master_Raw!$1:$1048576,5,FALSE) -> Marketing | F8: =VLOOKUP(A8,Employee_Master_Raw!$1:$1048576,6,FALSE) -> Analyst | G8: =VLOOKUP(A8,Employee_Master_Raw!$1:$1048576,7,FALSE) -> Unknown | H8: =IF(VLOOKUP(A8,Employee_Master_Raw!$1:$1048576,8,FALSE)=0,"",VLOOKUP(A8,Employee_Master_Raw!$1:$1048576,8,FALSE)) -> 45259 | I8: =VLOOKUP(A8,Employee_Master_Raw!$1:$1048576,9,FALSE) -> MBA | J8: =VLOOKUP(A8,Employee_Master_Raw!$1:$1048576,10,FALSE) -> 2 | K8: =VLOOKUP(A8,Employee_Master_Raw!$1:$1048576,11,FALSE) -> Sneha Thomas | L8: =VLOOKUP(A8,HR_Metrics_Raw!$1:$1048576,2,FALSE) -> 179676 | M8: =VLOOKUP(A8,HR_Metrics_Raw!$1:$1048576,3,FALSE) -> 3 | N8: =VLOOKUP(A8,HR_Metrics_Raw!$1:$1048576,4,FALSE) -> 6 | O8: =VLOOKUP(A8,HR_Metrics_Raw!$1:$1048576,5,FALSE) -> 1 | P8: =VLOOKUP(A8,HR_Metrics_Raw!$1:$1048576,6,FALSE) -> 28 | Q8: =VLOOKUP(A8,HR_Metrics_Raw!$1:$1048576,7,FALSE) -> Casual | R8: =VLOOKUP(A8,HR_Metrics_Raw!$1:$1048576,8,FALSE) -> No | S8: =VLOOKUP(A8,HR_Metrics_Raw!$1:$1048576,9,FALSE) -> 60 | T8: =VLOOKUP(A8,HR_Metrics_Raw!$1:$1048576,10,FALSE) -> No | U8: =VLOOKUP(A8,HR_Metrics_Raw!$1:$1048576,11,FALSE) -> No
A9: EMP11621 | B9: =VLOOKUP(Final_HR_Data!A9,Employee_Master_Raw!$1:$1048576,2,FALSE) -> Priya Menon | C9: =VLOOKUP(A9,Employee_Master_Raw!$1:$1048576,3,FALSE) -> Female | D9: =VLOOKUP(A9,Employee_Master_Raw!$1:$1048576,4,FALSE) -> 58 | E9: =VLOOKUP(A9,Employee_Master_Raw!$1:$1048576,5,FALSE) -> IT | F9: =VLOOKUP(A9,Employee_Master_Raw!$1:$1048576,6,FALSE) -> Specialist | G9: =VLOOKUP(A9,Employee_Master_Raw!$1:$1048576,7,FALSE) -> Pune | H9: =IF(VLOOKUP(A9,Employee_Master_Raw!$1:$1048576,8,FALSE)=0,"",VLOOKUP(A9,Employee_Master_Raw!$1:$1048576,8,FALSE)) -> 45250 | I9: =VLOOKUP(A9,Employee_Master_Raw!$1:$1048576,9,FALSE) -> MCA | J9: =VLOOKUP(A9,Employee_Master_Raw!$1:$1048576,10,FALSE) -> 11 | K9: =VLOOKUP(A9,Employee_Master_Raw!$1:$1048576,11,FALSE) -> Rahul Nair | L9: =VLOOKUP(A9,HR_Metrics_Raw!$1:$1048576,2,FALSE) -> 173440 | M9: =VLOOKUP(A9,HR_Metrics_Raw!$1:$1048576,3,FALSE) -> 1 | N9: =VLOOKUP(A9,HR_Metrics_Raw!$1:$1048576,4,FALSE) -> 5 | O9: =VLOOKUP(A9,HR_Metrics_Raw!$1:$1048576,5,FALSE) -> 0.919 | P9: =VLOOKUP(A9,HR_Metrics_Raw!$1:$1048576,6,FALSE) -> 1 | Q9: =VLOOKUP(A9,HR_Metrics_Raw!$1:$1048576,7,FALSE) -> Sick | R9: =VLOOKUP(A9,HR_Metrics_Raw!$1:$1048576,8,FALSE) -> Yes | S9: =VLOOKUP(A9,HR_Metrics_Raw!$1:$1048576,9,FALSE) -> 25 | T9: =VLOOKUP(A9,HR_Metrics_Raw!$1:$1048576,10,FALSE) -> No | U9: =VLOOKUP(A9,HR_Metrics_Raw!$1:$1048576,11,FALSE) -> No
A10: EMP12522 | B10: =VLOOKUP(Final_HR_Data!A10,Employee_Master_Raw!$1:$1048576,2,FALSE) -> Ananya Sharma | C10: =VLOOKUP(A10,Employee_Master_Raw!$1:$1048576,3,FALSE) -> Female | D10: =VLOOKUP(A10,Employee_Master_Raw!$1:$1048576,4,FALSE) -> 59 | E10: =VLOOKUP(A10,Employee_Master_Raw!$1:$1048576,5,FALSE) -> FINANCE | F10: =VLOOKUP(A10,Employee_Master_Raw!$1:$1048576,6,FALSE) -> Developer | G10: =VLOOKUP(A10,Employee_Master_Raw!$1:$1048576,7,FALSE) -> Mumbai | H10: =IF(VLOOKUP(A10,Employee_Master_Raw!$1:$1048576,8,FALSE)=0,"",VLOOKUP(A10,Employee_Master_Raw!$1:$1048576,8,FALSE)) -> 45426 | I10: =VLOOKUP(A10,Employee_Master_Raw!$1:$1048576,9,FALSE) -> Master's | J10: =VLOOKUP(A10,Employee_Master_Raw!$1:$1048576,10,FALSE) -> 7 | K10: =VLOOKUP(A10,Employee_Master_Raw!$1:$1048576,11,FALSE) -> Priya Sharma | L10: =VLOOKUP(A10,HR_Metrics_Raw!$1:$1048576,2,FALSE) -> 37409 | M10: =VLOOKUP(A10,HR_Metrics_Raw!$1:$1048576,3,FALSE) -> 4 | N10: =VLOOKUP(A10,HR_Metrics_Raw!$1:$1048576,4,FALSE) -> 6 | O10: =VLOOKUP(A10,HR_Metrics_Raw!$1:$1048576,5,FALSE) -> 0.976 | P10: =VLOOKUP(A10,HR_Metrics_Raw!$1:$1048576,6,FALSE) -> 28 | Q10: =VLOOKUP(A10,HR_Metrics_Raw!$1:$1048576,7,FALSE) -> Unknown | R10: =VLOOKUP(A10,HR_Metrics_Raw!$1:$1048576,8,FALSE) -> No | S10: =VLOOKUP(A10,HR_Metrics_Raw!$1:$1048576,9,FALSE) -> 51 | T10: =VLOOKUP(A10,HR_Metrics_Raw!$1:$1048576,10,FALSE) -> No | U10: =VLOOKUP(A10,HR_Metrics_Raw!$1:$1048576,11,FALSE) -> No
A11: EMP11646 | B11: =VLOOKUP(Final_HR_Data!A11,Employee_Master_Raw!$1:$1048576,2,FALSE) -> Priya Menon | C11: =VLOOKUP(A11,Employee_Master_Raw!$1:$1048576,3,FALSE) -> Male | D11: =VLOOKUP(A11,Employee_Master_Raw!$1:$1048576,4,FALSE) -> 42 | E11: =VLOOKUP(A11,Employee_Master_Raw!$1:$1048576,5,FALSE) -> Customer Support | F11: =VLOOKUP(A11,Employee_Master_Raw!$1:$1048576,6,FALSE) -> Manager | G11: =VLOOKUP(A11,Employee_Master_Raw!$1:$1048576,7,FALSE) -> Bangalore | H11: =IF(VLOOKUP(A11,Employee_Master_Raw!$1:$1048576,8,FALSE)=0,"",VLOOKUP(A11,Employee_Master_Raw!$1:$1048576,8,FALSE)) -> 44319 | I11: =VLOOKUP(A11,Employee_Master_Raw!$1:$1048576,9,FALSE) -> MBA | J11: =VLOOKUP(A11,Employee_Master_Raw!$1:$1048576,10,FALSE) -> 1 | K11: =VLOOKUP(A11,Employee_Master_Raw!$1:$1048576,11,FALSE) -> Sneha Thomas | L11: =VLOOKUP(A11,HR_Metrics_Raw!$1:$1048576,2,FALSE) -> 105129 | M11: =VLOOKUP(A11,HR_Metrics_Raw!$1:$1048576,3,FALSE) -> 5 | N11: =VLOOKUP(A11,HR_Metrics_Raw!$1:$1048576,4,FALSE) -> 9 | O11: =VLOOKUP(A11,HR_Metrics_Raw!$1:$1048576,5,FALSE) -> 0.917 | P11: =VLOOKUP(A11,HR_Metrics_Raw!$1:$1048576,6,FALSE) -> 21 | Q11: =VLOOKUP(A11,HR_Metrics_Raw!$1:$1048576,7,FALSE) -> Maternity/Paternity | R11: =VLOOKUP(A11,HR_Metrics_Raw!$1:$1048576,8,FALSE) -> No | S11: =VLOOKUP(A11,HR_Metrics_Raw!$1:$1048576,9,FALSE) -> 35 | T11: =VLOOKUP(A11,HR_Metrics_Raw!$1:$1048576,10,FALSE) -> No | U11: =VLOOKUP(A11,HR_Metrics_Raw!$1:$1048576,11,FALSE) -> No
A12: EMP10183 | B12: =VLOOKUP(Final_HR_Data!A12,Employee_Master_Raw!$1:$1048576,2,FALSE) -> Rahul Kumar | C12: =VLOOKUP(A12,Employee_Master_Raw!$1:$1048576,3,FALSE) -> Female | D12: =VLOOKUP(A12,Employee_Master_Raw!$1:$1048576,4,FALSE) -> 27 | E12: =VLOOKUP(A12,Employee_Master_Raw!$1:$1048576,5,FALSE) -> Customer Support | F12: =VLOOKUP(A12,Employee_Master_Raw!$1:$1048576,6,FALSE) -> Analyst | G12: =VLOOKUP(A12,Employee_Master_Raw!$1:$1048576,7,FALSE) -> Mumbai | H12: =IF(VLOOKUP(A12,Employee_Master_Raw!$1:$1048576,8,FALSE)=0,"",VLOOKUP(A12,Employee_Master_Raw!$1:$1048576,8,FALSE)) -> 42496 | I12: =VLOOKUP(A12,Employee_Master_Raw!$1:$1048576,9,FALSE) -> Bachelor's | J12: =VLOOKUP(A12,Employee_Master_Raw!$1:$1048576,10,FALSE) -> 16 | K12: =VLOOKUP(A12,Employee_Master_Raw!$1:$1048576,11,FALSE) -> Rahul Nair | L12: =VLOOKUP(A12,HR_Metrics_Raw!$1:$1048576,2,FALSE) -> 46078 | M12: =VLOOKUP(A12,HR_Metrics_Raw!$1:$1048576,3,FALSE) -> 4 | N12: =VLOOKUP(A12,HR_Metrics_Raw!$1:$1048576,4,FALSE) -> 3 | O12: =VLOOKUP(A12,HR_Metrics_Raw!$1:$1048576,5,FALSE) -> 0.845 | P12: =VLOOKUP(A12,HR_Metrics_Raw!$1:$1048576,6,FALSE) -> 23 | Q12: =VLOOKUP(A12,HR_Metrics_Raw!$1:$1048576,7,FALSE) -> Earned | R12: =VLOOKUP(A12,HR_Metrics_Raw!$1:$1048576,8,FALSE) -> No | S12: =VLOOKUP(A12,HR_Metrics_Raw!$1:$1048576,9,FALSE) -> 54 | T12: =VLOOKUP(A12,HR_Metrics_Raw!$1:$1048576,10,FALSE) -> No | U12: =VLOOKUP(A12,HR_Metrics_Raw!$1:$1048576,11,FALSE) -> No
A13: EMP11017 | B13: =VLOOKUP(Final_HR_Data!A13,Employee_Master_Raw!$1:$1048576,2,FALSE) -> Rahul Kumar | C13: =VLOOKUP(A13,Employee_Master_Raw!$1:$1048576,3,FALSE) -> Male | D13: =VLOOKUP(A13,Employee_Master_Raw!$1:$1048576,4,FALSE) -> 45 | E13: =VLOOKUP(A13,Employee_Master_Raw!$1:$1048576,5,FALSE) -> Operations | F13: =VLOOKUP(A13,Employee_Master_Raw!$1:$1048576,6,FALSE) -> Specialist | G13: =VLOOKUP(A13,Employee_Master_Raw!$1:$1048576,7,FALSE) -> Chennai | H13: =IF(VLOOKUP(A13,Employee_Master_Raw!$1:$1048576,8,FALSE)=0,"",VLOOKUP(A13,Employee_Master_Raw!$1:$1048576,8,FALSE)) -> 44058 | I13: =VLOOKUP(A13,Employee_Master_Raw!$1:$1048576,9,FALSE) -> MCA | J13: =VLOOKUP(A13,Employee_Master_Raw!$1:$1048576,10,FALSE) -> 6 | K13: =VLOOKUP(A13,Employee_Master_Raw!$1:$1048576,11,FALSE) -> Sneha Thomas | L13: =VLOOKUP(A13,HR_Metrics_Raw!$1:$1048576,2,FALSE) -> 53396 | M13: =VLOOKUP(A13,HR_Metrics_Raw!$1:$1048576,3,FALSE) -> 1 | N13: =VLOOKUP(A13,HR_Metrics_Raw!$1:$1048576,4,FALSE) -> 8 | O13: =VLOOKUP(A13,HR_Metrics_Raw!$1:$1048576,5,FALSE) -> 1 | P13: =VLOOKUP(A13,HR_Metrics_Raw!$1:$1048576,6,FALSE) -> 13 | Q13: =VLOOKUP(A13,HR_Metrics_Raw!$1:$1048576,7,FALSE) -> Maternity/Paternity | R13: =VLOOKUP(A13,HR_Metrics_Raw!$1:$1048576,8,FALSE) -> No | S13: =VLOOKUP(A13,HR_Metrics_Raw!$1:$1048576,9,FALSE) -> 17 | T13: =VLOOKUP(A13,HR_Metrics_Raw!$1:$1048576,10,FALSE) -> No | U13: =VLOOKUP(A13,HR_Metrics_Raw!$1:$1048576,11,FALSE) -> Yes
... A3001: EMP11147 | B3001: =VLOOKUP(Final_HR_Data!A3001,Employee_Master_Raw!$1:$1048576,2,FALSE) -> Neha Thomas | C3001: =VLOOKUP(A3001,Employee_Master_Raw!$1:$1048576,3,FALSE) -> Male | D3001: =VLOOKUP(A3001,Employee_Master_Raw!$1:$1048576,4,FALSE) -> 56 | E3001: =VLOOKUP(A3001,Employee_Master_Raw!$1:$1048576,5,FALSE) -> Customer Support | F3001: =VLOOKUP(A3001,Employee_Master_Raw!$1:$1048576,6,FALSE) -> Executive | G3001: =VLOOKUP(A3001,Employee_Master_Raw!$1:$1048576,7,FALSE) -> Chennai | H3001: =IF(VLOOKUP(A3001,Employee_Master_Raw!$1:$1048576,8,FALSE)=0,"",VLOOKUP(A3001,Employee_Master_Raw!$1:$1048576,8,FALSE)) -> 43328 | I3001: =VLOOKUP(A3001,Employee_Master_Raw!$1:$1048576,9,FALSE) -> Master's | J3001: =VLOOKUP(A3001,Employee_Master_Raw!$1:$1048576,10,FALSE) -> 2 | K3001: =VLOOKUP(A3001,Employee_Master_Raw!$1:$1048576,11,FALSE) -> Anil Menon | L3001: =VLOOKUP(A3001,HR_Metrics_Raw!$1:$1048576,2,FALSE) -> 126039 | M3001: =VLOOKUP(A3001,HR_Metrics_Raw!$1:$1048576,3,FALSE) -> 3 | N3001: =VLOOKUP(A3001,HR_Metrics_Raw!$1:$1048576,4,FALSE) -> 9 | O3001: =VLOOKUP(A3001,HR_Metrics_Raw!$1:$1048576,5,FALSE) -> 1 | P3001: =VLOOKUP(A3001,HR_Metrics_Raw!$1:$1048576,6,FALSE) -> 0 | Q3001: =VLOOKUP(A3001,HR_Metrics_Raw!$1:$1048576,7,FALSE) -> Unpaid | R3001: =VLOOKUP(A3001,HR_Metrics_Raw!$1:$1048576,8,FALSE) -> Yes | S3001: =VLOOKUP(A3001,HR_Metrics_Raw!$1:$1048576,9,FALSE) -> 14 | T3001: =VLOOKUP(A3001,HR_Metrics_Raw!$1:$1048576,10,FALSE) -> No | U3001: =VLOOKUP(A3001,HR_Metrics_Raw!$1:$1048576,11,FALSE) -> No

Sheet Pivot Tables
A1: Row Labels | B1: Count of Employee ID | L1: Count of Employee ID | M1: Column Labels
A2: Customer Support | B2: 399 | L2: Row Labels | M2: No | N2: Yes | O2: Grand Total
A3: FINANCE | B3: 460 | L3: Customer Support | M3: 355 | N3: 44 | O3: 399
A4: HR | B4: 409 | L4: FINANCE | M4: 412 | N4: 48 | O4: 460
A5: IT | B5: 421 | L5: HR | M5: 370 | N5: 39 | O5: 409
A6: Marketing | B6: 447 | L6: IT | M6: 367 | N6: 54 | O6: 421
A7: Operations | B7: 407 | L7: Marketing | M7: 388 | N7: 59 | O7: 447
A8: Sales | B8: 413 | L8: Operations | M8: 360 | N8: 47 | O8: 407
A9: Unknown | B9: 44 | L9: Sales | M9: 355 | N9: 58 | O9: 413
A10: Grand Total | B10: 3000 | L10: Unknown | M10: 37 | N10: 7 | O10: 44
L11: Grand Total | M11: 2644 | N11: 356 | O11: 3000
A20: Row Labels | B20: Average of Monthly Salary | M20: Row Labels | N20: Average of Performance Rating
A21: Customer Support | B21: 101334.76 | M21: Customer Support | N21: 3.047619
A22: FINANCE | B22: 101435.41 | M22: FINANCE | N22: 3.0282609
A23: HR | B23: 104271.08 | M23: HR | N23: 3.1369193
A24: IT | B24: 103093.3 | M24: IT | N24: 2.9667458
A25: Marketing | B25: 102315.69 | M25: Marketing | N25: 2.8903803
A26: Operations | B26: 106284.69 | M26: Operations | N26: 3.022113
A27: Sales | B27: 101381.63 | M27: Sales | N27: 2.9588378
A28: Unknown | B28: 112102.34 | M28: Unknown | N28: 2.9318182
A29: Grand Total | B29: 102979.37 | M29: Grand Total | N29: 3.0046667
L37: Row Labels | M37: Count of Employee ID
A38: Row Labels | B38: Average of Job Satisfaction | L38: Casual | M38: 597
A39: Customer Support | B39: 5.4661654 | L39: Earned | M39: 569
A40: FINANCE | B40: 5.2369565 | L40: Maternity/Paternity | M40: 582
A41: HR | B41: 5.7017115 | L41: Sick | M41: 647
A42: IT | B42: 5.6033254 | L42: Unknown | M42: 46
A43: Marketing | B43: 5.1991051 | L43: Unpaid | M43: 559
A44: Operations | B44: 5.3808354 | L44: Grand Total | M44: 3000
A45: Sales | B45: 5.5060533
A46: Unknown | B46: 5.8181818
A47: Grand Total | B47: 5.4416667
A54: Count of Employee ID | B54: Column Labels | N54: Row Labels | O54: Average of Training Hours
A55: Row Labels | B55: No | C55: Yes | D55: Grand Total | N55: Customer Support | O55: 40.581454
A56: Customer Support | B56: 273 | C56: 126 | D56: 399 | N56: FINANCE | O56: 39.41087
A57: FINANCE | B57: 346 | C57: 114 | D57: 460 | N57: HR | O57: 39.403423
A58: HR | B58: 303 | C58: 106 | D58: 409 | N58: IT | O58: 39.76247
A59: IT | B59: 292 | C59: 129 | D59: 421 | N59: Marketing | O59: 38.818792
A60: Marketing | B60: 317 | C60: 130 | D60: 447 | N60: Operations | O60: 39.058968
A61: Operations | B61: 301 | C61: 106 | D61: 407 | N61: Sales | O61: 42.012107
...
